<?xml version="1.0" encoding="utf-8"?>
<!-- This URDF was automatically created by SolidWorks to URDF Exporter! Originally created by Stephen Brawner (brawner@gmail.com) 
     Commit Version: 1.6.0-4-g7f85cfe  Build Version: 1.6.7995.38578
     For more information, please see http://wiki.ros.org/sw_urdf_exporter -->
<robot
  name="spider_SLDASM_2m6d">
  <link
    name="base_link">
    <inertial>
      <origin
        xyz="0.008816 0 -0.005958"
        rpy="0 0 0" />
      <mass
        value="7.61" />
      <inertia
        ixx="0.067729"
        ixy="0"
        ixz="-0.0042236"
        iyy="0.0725"
        iyz="0"
        izz="0.12513" />
    </inertial>
    <visual>
      <origin
        xyz="0 0 0"
        rpy="0 0 0" />
      <geometry>
        <mesh
          filename="/home/zenbot-ljl/placo_spider/spider_SLDASM_2m6d/meshes/base_link.STL" />
      </geometry>
      <material
        name="">
        <color
          rgba="0.79216 0.81961 0.93333 1" />
      </material>
    </visual>
    <collision>
      <origin
        xyz="0 0 0"
        rpy="0 0 0" />
      <geometry>
        <mesh
          filename="/home/zenbot-ljl/placo_spider/spider_SLDASM_2m6d/meshes/base_link.STL" />
      </geometry>
    </collision>
  </link>
  <link
    name="FR_hip">
    <inertial>
      <origin
        xyz="0.082474 0 0.000806"
        rpy="0 0 0" />
      <mass
        value="1.9015" />
      <inertia
        ixx="0.00332"
        ixy="0"
        ixz="0.00015402"
        iyy="0.0066457"
        iyz="0"
        izz="0.004961" />
    </inertial>
    <visual>
      <origin
        xyz="0 0 0"
        rpy="0 0 0" />
      <geometry>
        <mesh
          filename="/home/zenbot-ljl/placo_spider/spider_SLDASM_2m6d/meshes/FR_hip.STL" />
      </geometry>
      <material
        name="">
        <color
          rgba="0.79216 0.81961 0.93333 1" />
      </material>
    </visual>
    <collision>
      <origin
        xyz="0 0 0"
        rpy="0 0 0" />
      <geometry>
        <mesh
          filename="/home/zenbot-ljl/placo_spider/spider_SLDASM_2m6d/meshes/FR_hip.STL" />
      </geometry>
    </collision>
  </link>
  <joint
    name="FR_hip_joint_rev"
    type="revolute">
    <origin
      xyz="0.15 -0.15 -0.00525"
      rpy="0 0 -0.7854" />
    <parent
      link="base_link" />
    <child
      link="FR_hip" />
    <axis
      xyz="0 0 1" />
    <limit
      lower="-1.1345"
      upper="1.1345"
      effort="0"
      velocity="0" />
  </joint>
  <link
    name="FR_thigh">
    <inertial>
      <origin
        xyz="0.084796 0 0.004794"
        rpy="0 0 0" />
      <mass
        value="0.6009" />
      <inertia
        ixx="0.0013857"
        ixy="0"
        ixz="-6.6099E-06"
        iyy="0.0023339"
        iyz="0"
        izz="0.0031649" />
    </inertial>
    <visual>
      <origin
        xyz="0 0 0"
        rpy="0 0 0" />
      <geometry>
        <mesh
          filename="/home/zenbot-ljl/placo_spider/spider_SLDASM_2m6d/meshes/FR_thigh.STL" />
      </geometry>
      <material
        name="">
        <color
          rgba="0.79216 0.81961 0.93333 1" />
      </material>
    </visual>
    <collision>
      <origin
        xyz="0 0 0"
        rpy="0 0 0" />
      <geometry>
        <mesh
          filename="/home/zenbot-ljl/placo_spider/spider_SLDASM_2m6d/meshes/FR_thigh.STL" />
      </geometry>
    </collision>
  </link>
  <joint
    name="FR_thigh_joint_rev"
    type="revolute">
    <origin
      xyz="0.122 -0.0005 0"
      rpy="0 0 0" />
    <parent
      link="FR_hip" />
    <child
      link="FR_thigh" />
    <axis
      xyz="0 1 0" />
    <limit
      lower="-1.0472"
      upper="1.5708"
      effort="0"
      velocity="0" />
  </joint>
  <link
    name="FR_calf">
    <inertial>
      <origin
        xyz="0.020656 0 -0.035012"
        rpy="0 0 0" />
      <mass
        value="0.95" />
      <inertia
        ixx="0.0014545"
        ixy="0"
        ixz="0.0003838"
        iyy="0.0017157"
        iyz="0"
        izz="0.00086925" />
    </inertial>
    <visual>
      <origin
        xyz="0 0 0"
        rpy="0 0 0" />
      <geometry>
        <mesh
          filename="/home/zenbot-ljl/placo_spider/spider_SLDASM_2m6d/meshes/FR_calf.STL" />
      </geometry>
      <material
        name="">
        <color
          rgba="0.79216 0.81961 0.93333 1" />
      </material>
    </visual>
    <collision>
      <origin
        xyz="0 0 0"
        rpy="0 0 0" />
      <geometry>
        <mesh
          filename="/home/zenbot-ljl/placo_spider/spider_SLDASM_2m6d/meshes/FR_calf.STL" />
      </geometry>
    </collision>
  </link>
  <joint
    name="FR_calf_joint_rev"
    type="revolute">
    <origin
      xyz="0.16 0 0"
      rpy="0 0 0" />
    <parent
      link="FR_thigh" />
    <child
      link="FR_calf" />
    <axis
      xyz="0 1 0" />
    <limit
      lower="-1.5707963268"
      upper="1.0471975512"
      effort="0"
      velocity="0" />
  </joint>
  <link
    name="FR_steer">
    <inertial>
      <origin
        xyz="-0.010789 0 -0.038549"
        rpy="0 0 0" />
      <mass
        value="0.4937" />
      <inertia
        ixx="0.00032831"
        ixy="0"
        ixz="-8.8866E-06"
        iyy="0.00032683"
        iyz="0"
        izz="0.00023698" />
    </inertial>
    <visual>
      <origin
        xyz="0 0 0"
        rpy="0 0 0" />
      <geometry>
        <mesh
          filename="/home/zenbot-ljl/placo_spider/spider_SLDASM_2m6d/meshes/FR_steer.STL" />
      </geometry>
      <material
        name="">
        <color
          rgba="1 1 1 1" />
      </material>
    </visual>
    <collision>
      <origin
        xyz="0 0 0"
        rpy="0 0 0" />
      <geometry>
        <mesh
          filename="/home/zenbot-ljl/placo_spider/spider_SLDASM_2m6d/meshes/FR_steer.STL" />
      </geometry>
    </collision>
  </link>
  <joint
    name="FR_steer_joint_rev"
    type="fixed">
    <origin
      xyz="0.033 0 -0.097"
      rpy="0 0 0" />
    <parent
      link="FR_calf" />
    <child
      link="FR_steer" />
    <!-- <axis
      xyz="0 0 1" />
    <limit
      lower="-0.34907"
      upper="1.5708"
      effort="0"
      velocity="0" /> -->
  </joint>
  <link
    name="FR_trans">
    <inertial>
      <origin
        xyz="-4.1E-05 -8.8E-05 -0.045108"
        rpy="0 0 0" />
      <mass
        value="0.4204" />
      <inertia
        ixx="0.00030185"
        ixy="-4.204E-07"
        ixz="8.408E-07"
        iyy="0.00030059"
        iyz="1.6816E-06"
        izz="0.00020305" />
    </inertial>
    <visual>
      <origin
        xyz="0 0 0"
        rpy="0 0 0" />
      <geometry>
        <mesh
          filename="/home/zenbot-ljl/placo_spider/spider_SLDASM_2m6d/meshes/FR_trans.STL" />
      </geometry>
      <material
        name="">
        <color
          rgba="0.79216 0.81961 0.93333 1" />
      </material>
    </visual>
    <collision>
      <origin
        xyz="0 0 0"
        rpy="0 0 0" />
      <geometry>
        <mesh
          filename="/home/zenbot-ljl/placo_spider/spider_SLDASM_2m6d/meshes/FR_trans.STL" />
      </geometry>
    </collision>
  </link>
  <joint
    name="FR_trans_joint_rev"
    type="fixed">
    <origin
      xyz="-0.00099998 0 -0.09"
      rpy="0 0 0" />
    <parent
      link="FR_steer" />
    <child
      link="FR_trans" />
    <!-- <axis
      xyz="0 1 0" />
    <limit
      lower="-1.5708"
      upper="0"
      effort="0"
      velocity="0" /> -->
  </joint>
  <link
    name="FR_wheel">
    <inertial>
      <origin
        xyz="0 0 0.022661"
        rpy="0 0 0" />
      <mass
        value="0.536" />
      <inertia
        ixx="0.00073807"
        ixy="0"
        ixz="0"
        iyy="0.00073807"
        iyz="0"
        izz="0.0011063" />
    </inertial>
    <visual>
      <origin
        xyz="0 0 0"
        rpy="0 0 0" />
      <geometry>
        <mesh
          filename="/home/zenbot-ljl/placo_spider/spider_SLDASM_2m6d/meshes/FR_wheel.STL" />
      </geometry>
      <material
        name="">
        <color
          rgba="1 1 1 1" />
      </material>
    </visual>
    <collision>
      <origin
        xyz="0 0 0"
        rpy="0 0 0" />
      <geometry>
        <mesh
          filename="/home/zenbot-ljl/placo_spider/spider_SLDASM_2m6d/meshes/FR_wheel.STL" />
      </geometry>
    </collision>
  </link>
  <joint
    name="FR_wheel_joint_con"
    type="fixed">
    <origin
      xyz="0 0 -0.083"
      rpy="0 0 0" />
    <parent
      link="FR_trans" />
    <child
      link="FR_wheel" />
    <!-- <axis
      xyz="0 0 1" />
    <limit
      lower="-1"
      upper="1"
      effort="0"
      velocity="0" /> -->
  </joint>
  <link
    name="FL_hip">
    <inertial>
      <origin
        xyz="0.082474 0 0.000806"
        rpy="0 0 0" />
      <mass
        value="1.9015" />
      <inertia
        ixx="0.00332"
        ixy="0"
        ixz="0.00015402"
        iyy="0.0066457"
        iyz="0"
        izz="0.004961" />
    </inertial>
    <visual>
      <origin
        xyz="0 0 0"
        rpy="0 0 0" />
      <geometry>
        <mesh
          filename="/home/zenbot-ljl/placo_spider/spider_SLDASM_2m6d/meshes/FL_hip.STL" />
      </geometry>
      <material
        name="">
        <color
          rgba="0.79216 0.81961 0.93333 1" />
      </material>
    </visual>
    <collision>
      <origin
        xyz="0 0 0"
        rpy="0 0 0" />
      <geometry>
        <mesh
          filename="/home/zenbot-ljl/placo_spider/spider_SLDASM_2m6d/meshes/FL_hip.STL" />
      </geometry>
    </collision>
  </link>
  <joint
    name="FL_hip_joint_rev"
    type="revolute">
    <origin
      xyz="0.15 0.15 -0.00525"
      rpy="0 0 0.7854" />
    <parent
      link="base_link" />
    <child
      link="FL_hip" />
    <axis
      xyz="0 0 1" />
    <limit
      lower="-1.1345"
      upper="1.1345"
      effort="0"
      velocity="0" />
  </joint>
  <link
    name="FL_thigh">
    <inertial>
      <origin
        xyz="0.084796 0 0.004794"
        rpy="0 0 0" />
      <mass
        value="0.6009" />
      <inertia
        ixx="0.0013857"
        ixy="0"
        ixz="-6.6099E-06"
        iyy="0.0023339"
        iyz="0"
        izz="0.0031649" />
    </inertial>
    <visual>
      <origin
        xyz="0 0 0"
        rpy="0 0 0" />
      <geometry>
        <mesh
          filename="/home/zenbot-ljl/placo_spider/spider_SLDASM_2m6d/meshes/FL_thigh.STL" />
      </geometry>
      <material
        name="">
        <color
          rgba="0.79216 0.81961 0.93333 1" />
      </material>
    </visual>
    <collision>
      <origin
        xyz="0 0 0"
        rpy="0 0 0" />
      <geometry>
        <mesh
          filename="/home/zenbot-ljl/placo_spider/spider_SLDASM_2m6d/meshes/FL_thigh.STL" />
      </geometry>
    </collision>
  </link>
  <joint
    name="FL_thigh_joint_rev"
    type="revolute">
    <origin
      xyz="0.122 -0.0005 0"
      rpy="0 0 0" />
    <parent
      link="FL_hip" />
    <child
      link="FL_thigh" />
    <axis
      xyz="0 1 0" />
    <limit
      lower="-1.0472"
      upper="1.5708"
      effort="0"
      velocity="0" />
  </joint>
  <link
    name="FL_calf">
    <inertial>
      <origin
        xyz="0.020656 0 -0.035012"
        rpy="0 0 0" />
      <mass
        value="0.95" />
      <inertia
        ixx="0.0014545"
        ixy="0"
        ixz="0.0003838"
        iyy="0.0017157"
        iyz="0"
        izz="0.00086925" />
    </inertial>
    <visual>
      <origin
        xyz="0 0 0"
        rpy="0 0 0" />
      <geometry>
        <mesh
          filename="/home/zenbot-ljl/placo_spider/spider_SLDASM_2m6d/meshes/FL_calf.STL" />
      </geometry>
      <material
        name="">
        <color
          rgba="0.79216 0.81961 0.93333 1" />
      </material>
    </visual>
    <collision>
      <origin
        xyz="0 0 0"
        rpy="0 0 0" />
      <geometry>
        <mesh
          filename="/home/zenbot-ljl/placo_spider/spider_SLDASM_2m6d/meshes/FL_calf.STL" />
      </geometry>
    </collision>
  </link>
  <joint
    name="FL_calf_joint_rev"
    type="revolute">
    <origin
      xyz="0.16 0 0"
      rpy="0 0 0" />
    <parent
      link="FL_thigh" />
    <child
      link="FL_calf" />
    <axis
      xyz="0 1 0" />
    <limit
      lower="-1.5707963267948966"
      upper="1.0471975512"
      effort="0"
      velocity="0" />
  </joint>
  <link
    name="FL_steer">
    <inertial>
      <origin
        xyz="-0.010789 0 -0.038549"
        rpy="0 0 0" />
      <mass
        value="0.4937" />
      <inertia
        ixx="0.00032831"
        ixy="0"
        ixz="-8.8866E-06"
        iyy="0.00032683"
        iyz="0"
        izz="0.00023698" />
    </inertial>
    <visual>
      <origin
        xyz="0 0 0"
        rpy="0 0 0" />
      <geometry>
        <mesh
          filename="/home/zenbot-ljl/placo_spider/spider_SLDASM_2m6d/meshes/FL_steer.STL" />
      </geometry>
      <material
        name="">
        <color
          rgba="1 1 1 1" />
      </material>
    </visual>
    <collision>
      <origin
        xyz="0 0 0"
        rpy="0 0 0" />
      <geometry>
        <mesh
          filename="/home/zenbot-ljl/placo_spider/spider_SLDASM_2m6d/meshes/FL_steer.STL" />
      </geometry>
    </collision>
  </link>
  <joint
    name="FL_steer_joint_rev"
    type="fixed">
    <origin
      xyz="0.033 0 -0.097"
      rpy="0 0 0" />
    <parent
      link="FL_calf" />
    <child
      link="FL_steer" />
    <!-- <axis
      xyz="0 0 1" />
    <limit
      lower="-0.3490658503988659"
      upper="1.5707963267948966"
      effort="0"
      velocity="0" /> -->
  </joint>
  <link
    name="FL_trans">
    <inertial>
      <origin
        xyz="-4.1E-05 -8.8E-05 -0.045108"
        rpy="0 0 0" />
      <mass
        value="0.4204" />
      <inertia
        ixx="0.00030185"
        ixy="-4.204E-07"
        ixz="8.408E-07"
        iyy="0.00030059"
        iyz="1.6816E-06"
        izz="0.00020305" />
    </inertial>
    <visual>
      <origin
        xyz="0 0 0"
        rpy="0 0 0" />
      <geometry>
        <mesh
          filename="/home/zenbot-ljl/placo_spider/spider_SLDASM_2m6d/meshes/FL_trans.STL" />
      </geometry>
      <material
        name="">
        <color
          rgba="0.79216 0.81961 0.93333 1" />
      </material>
    </visual>
    <collision>
      <origin
        xyz="0 0 0"
        rpy="0 0 0" />
      <geometry>
        <mesh
          filename="/home/zenbot-ljl/placo_spider/spider_SLDASM_2m6d/meshes/FL_trans.STL" />
      </geometry>
    </collision>
  </link>
  <joint
    name="FL_trans_joint_rev"
    type="fixed">
    <origin
      xyz="-0.00099998 0 -0.09"
      rpy="0 0 0" />
    <parent
      link="FL_steer" />
    <child
      link="FL_trans" />
    <!-- <axis
      xyz="0 1 0" />
    <limit
      lower="-1.5708"
      upper="0"
      effort="0"
      velocity="0" /> -->
  </joint>
  <link
    name="FL_wheel">
    <inertial>
      <origin
        xyz="0 0 0.022661"
        rpy="0 0 0" />
      <mass
        value="0.536" />
      <inertia
        ixx="0.00073807"
        ixy="0"
        ixz="0"
        iyy="0.00073807"
        iyz="0"
        izz="0.0011063" />
    </inertial>
    <visual>
      <origin
        xyz="0 0 0"
        rpy="0 0 0" />
      <geometry>
        <mesh
          filename="/home/zenbot-ljl/placo_spider/spider_SLDASM_2m6d/meshes/FL_wheel.STL" />
      </geometry>
      <material
        name="">
        <color
          rgba="1 1 1 1" />
      </material>
    </visual>
    <collision>
      <origin
        xyz="0 0 0"
        rpy="0 0 0" />
      <geometry>
        <mesh
          filename="/home/zenbot-ljl/placo_spider/spider_SLDASM_2m6d/meshes/FL_wheel.STL" />
      </geometry>
    </collision>
  </link>
  <joint
    name="FL_wheel_joint_con"
    type="fixed">
    <origin
      xyz="0 0 -0.083"
      rpy="0 0 0" />
    <parent
      link="FL_trans" />
    <child
      link="FL_wheel" />
    <!-- <axis
      xyz="0 0 1" />
    <limit
      lower="-1"
      upper="1"
      effort="0"
      velocity="0" /> -->
  </joint>
  <link
    name="RL_hip">
    <inertial>
      <origin
        xyz="0.082474 0 0.000806"
        rpy="0 0 0" />
      <mass
        value="1.9015" />
      <inertia
        ixx="0.00332"
        ixy="0"
        ixz="0.00015402"
        iyy="0.0066457"
        iyz="0"
        izz="0.004961" />
    </inertial>
    <visual>
      <origin
        xyz="0 0 0"
        rpy="0 0 0" />
      <geometry>
        <mesh
          filename="/home/zenbot-ljl/placo_spider/spider_SLDASM_2m6d/meshes/RL_hip.STL" />
      </geometry>
      <material
        name="">
        <color
          rgba="0.79216 0.81961 0.93333 1" />
      </material>
    </visual>
    <collision>
      <origin
        xyz="0 0 0"
        rpy="0 0 0" />
      <geometry>
        <mesh
          filename="/home/zenbot-ljl/placo_spider/spider_SLDASM_2m6d/meshes/RL_hip.STL" />
      </geometry>
    </collision>
  </link>
  <joint
    name="RL_hip_joint_rev"
    type="revolute">
    <origin
      xyz="-0.15 0.15 -0.00525"
      rpy="0 0 2.3562" />
    <parent
      link="base_link" />
    <child
      link="RL_hip" />
    <axis
      xyz="0 0 1" />
    <limit
      lower="-1.1345"
      upper="1.1345"
      effort="0"
      velocity="0" />
  </joint>
  <link
    name="RL_thigh">
    <inertial>
      <origin
        xyz="0.084796 0 0.004794"
        rpy="0 0 0" />
      <mass
        value="0.6009" />
      <inertia
        ixx="0.0013857"
        ixy="0"
        ixz="-6.6099E-06"
        iyy="0.0023339"
        iyz="0"
        izz="0.0031649" />
    </inertial>
    <visual>
      <origin
        xyz="0 0 0"
        rpy="0 0 0" />
      <geometry>
        <mesh
          filename="/home/zenbot-ljl/placo_spider/spider_SLDASM_2m6d/meshes/RL_thigh.STL" />
      </geometry>
      <material
        name="">
        <color
          rgba="0.79216 0.81961 0.93333 1" />
      </material>
    </visual>
    <collision>
      <origin
        xyz="0 0 0"
        rpy="0 0 0" />
      <geometry>
        <mesh
          filename="/home/zenbot-ljl/placo_spider/spider_SLDASM_2m6d/meshes/RL_thigh.STL" />
      </geometry>
    </collision>
  </link>
  <joint
    name="RL_thigh_joint_rev"
    type="revolute">
    <origin
      xyz="0.122 -0.0005 0"
      rpy="0 0 0" />
    <parent
      link="RL_hip" />
    <child
      link="RL_thigh" />
    <axis
      xyz="0 1 0" />
    <limit
      lower="-1.0472"
      upper="1.5708"
      effort="0"
      velocity="0" />
  </joint>
  <link
    name="RL_calf">
    <inertial>
      <origin
        xyz="0.020656 0 -0.035012"
        rpy="0 0 0" />
      <mass
        value="0.95" />
      <inertia
        ixx="0.0014545"
        ixy="0"
        ixz="0.0003838"
        iyy="0.0017157"
        iyz="0"
        izz="0.00086925" />
    </inertial>
    <visual>
      <origin
        xyz="0 0 0"
        rpy="0 0 0" />
      <geometry>
        <mesh
          filename="/home/zenbot-ljl/placo_spider/spider_SLDASM_2m6d/meshes/RL_calf.STL" />
      </geometry>
      <material
        name="">
        <color
          rgba="0.79216 0.81961 0.93333 1" />
      </material>
    </visual>
    <collision>
      <origin
        xyz="0 0 0"
        rpy="0 0 0" />
      <geometry>
        <mesh
          filename="/home/zenbot-ljl/placo_spider/spider_SLDASM_2m6d/meshes/RL_calf.STL" />
      </geometry>
    </collision>
  </link>
  <joint
    name="RL_calf_joint_rev"
    type="revolute">
    <origin
      xyz="0.16 0 0"
      rpy="0 0 0" />
    <parent
      link="RL_thigh" />
    <child
      link="RL_calf" />
    <axis
      xyz="0 1 0" />
    <limit
      lower="-1.5707963268"
      upper="1.0471975512"
      effort="0"
      velocity="0" />
  </joint>
  <link
    name="RL_steer">
    <inertial>
      <origin
        xyz="-0.010789 0 -0.038549"
        rpy="0 0 0" />
      <mass
        value="0.4937" />
      <inertia
        ixx="0.00032831"
        ixy="0"
        ixz="-8.8866E-06"
        iyy="0.00032683"
        iyz="0"
        izz="0.00023698" />
    </inertial>
    <visual>
      <origin
        xyz="0 0 0"
        rpy="0 0 0" />
      <geometry>
        <mesh
          filename="/home/zenbot-ljl/placo_spider/spider_SLDASM_2m6d/meshes/RL_steer.STL" />
      </geometry>
      <material
        name="">
        <color
          rgba="1 1 1 1" />
      </material>
    </visual>
    <collision>
      <origin
        xyz="0 0 0"
        rpy="0 0 0" />
      <geometry>
        <mesh
          filename="/home/zenbot-ljl/placo_spider/spider_SLDASM_2m6d/meshes/RL_steer.STL" />
      </geometry>
    </collision>
  </link>
  <joint
    name="RL_steer_joint_rev"
    type="fixed">
    <origin
      xyz="0.033 0 -0.097"
      rpy="0 0 0" />
    <parent
      link="RL_calf" />
    <child
      link="RL_steer" />
    <!-- <axis
      xyz="0 0 1" />
    <limit
      lower="-0.34907"
      upper="1.5708"
      effort="0"
      velocity="0" /> -->
  </joint>
  <link
    name="RL_trans">
    <inertial>
      <origin
        xyz="-4.1E-05 -8.8E-05 -0.045108"
        rpy="0 0 0" />
      <mass
        value="0.4204" />
      <inertia
        ixx="0.00030185"
        ixy="-4.204E-07"
        ixz="8.408E-07"
        iyy="0.00030059"
        iyz="1.6816E-06"
        izz="0.00020305" />
    </inertial>
    <visual>
      <origin
        xyz="0 0 0"
        rpy="0 0 0" />
      <geometry>
        <mesh
          filename="/home/zenbot-ljl/placo_spider/spider_SLDASM_2m6d/meshes/RL_trans.STL" />
      </geometry>
      <material
        name="">
        <color
          rgba="0.79216 0.81961 0.93333 1" />
      </material>
    </visual>
    <collision>
      <origin
        xyz="0 0 0"
        rpy="0 0 0" />
      <geometry>
        <mesh
          filename="/home/zenbot-ljl/placo_spider/spider_SLDASM_2m6d/meshes/RL_trans.STL" />
      </geometry>
    </collision>
  </link>
  <joint
    name="RL_trans_joint_rev"
    type="fixed">
    <origin
      xyz="-0.00099998 0 -0.09"
      rpy="0 0 0" />
    <parent
      link="RL_steer" />
    <child
      link="RL_trans" />
    <!-- <axis
      xyz="0 1 0" />
    <limit
      lower="-1.5708"
      upper="0"
      effort="0"
      velocity="0" /> -->
  </joint>
  <link
    name="RL_wheel">
    <inertial>
      <origin
        xyz="0 0 0.022661"
        rpy="0 0 0" />
      <mass
        value="0.536" />
      <inertia
        ixx="0.00073807"
        ixy="0"
        ixz="0"
        iyy="0.00073807"
        iyz="0"
        izz="0.0011063" />
    </inertial>
    <visual>
      <origin
        xyz="0 0 0"
        rpy="0 0 0" />
      <geometry>
        <mesh
          filename="/home/zenbot-ljl/placo_spider/spider_SLDASM_2m6d/meshes/RL_wheel.STL" />
      </geometry>
      <material
        name="">
        <color
          rgba="1 1 1 1" />
      </material>
    </visual>
    <collision>
      <origin
        xyz="0 0 0"
        rpy="0 0 0" />
      <geometry>
        <mesh
          filename="/home/zenbot-ljl/placo_spider/spider_SLDASM_2m6d/meshes/RL_wheel.STL" />
      </geometry>
    </collision>
  </link>
  <joint
    name="RL_wheel_joint_con"
    type="fixed">
    <origin
      xyz="0 0 -0.083"
      rpy="0 0 0" />
    <parent
      link="RL_trans" />
    <child
      link="RL_wheel" />
    <!-- <axis
      xyz="0 0 1" />
    <limit
      lower="-1"
      upper="1"
      effort="0"
      velocity="0" /> -->
  </joint>
  <link
    name="RR_hip">
    <inertial>
      <origin
        xyz="0.082474 0 0.000806"
        rpy="0 0 0" />
      <mass
        value="1.9015" />
      <inertia
        ixx="0.00332"
        ixy="0"
        ixz="0.00015402"
        iyy="0.0066457"
        iyz="0"
        izz="0.004961" />
    </inertial>
    <visual>
      <origin
        xyz="0 0 0"
        rpy="0 0 0" />
      <geometry>
        <mesh
          filename="/home/zenbot-ljl/placo_spider/spider_SLDASM_2m6d/meshes/RR_hip.STL" />
      </geometry>
      <material
        name="">
        <color
          rgba="0.79216 0.81961 0.93333 1" />
      </material>
    </visual>
    <collision>
      <origin
        xyz="0 0 0"
        rpy="0 0 0" />
      <geometry>
        <mesh
          filename="/home/zenbot-ljl/placo_spider/spider_SLDASM_2m6d/meshes/RR_hip.STL" />
      </geometry>
    </collision>
  </link>
  <joint
    name="RR_hip_joint_rev"
    type="revolute">
    <origin
      xyz="-0.15 -0.15 -0.00525"
      rpy="0 0 -2.3562" />
    <parent
      link="base_link" />
    <child
      link="RR_hip" />
    <axis
      xyz="0 0 1" />
    <limit
      lower="-1.1345"
      upper="1.1345"
      effort="0"
      velocity="0" />
  </joint>
  <link
    name="RR_thigh">
    <inertial>
      <origin
        xyz="0.084796 0 0.004794"
        rpy="0 0 0" />
      <mass
        value="0.6009" />
      <inertia
        ixx="0.0013857"
        ixy="0"
        ixz="-6.6099E-06"
        iyy="0.0023339"
        iyz="0"
        izz="0.0031649" />
    </inertial>
    <visual>
      <origin
        xyz="0 0 0"
        rpy="0 0 0" />
      <geometry>
        <mesh
          filename="/home/zenbot-ljl/placo_spider/spider_SLDASM_2m6d/meshes/RR_thigh.STL" />
      </geometry>
      <material
        name="">
        <color
          rgba="0.79216 0.81961 0.93333 1" />
      </material>
    </visual>
    <collision>
      <origin
        xyz="0 0 0"
        rpy="0 0 0" />
      <geometry>
        <mesh
          filename="/home/zenbot-ljl/placo_spider/spider_SLDASM_2m6d/meshes/RR_thigh.STL" />
      </geometry>
    </collision>
  </link>
  <joint
    name="RR_thigh_joint_rev"
    type="revolute">
    <origin
      xyz="0.122 -0.0005 0"
      rpy="0 0 0" />
    <parent
      link="RR_hip" />
    <child
      link="RR_thigh" />
    <axis
      xyz="0 1 0" />
    <limit
      lower="-1.0472"
      upper="1.5708"
      effort="0"
      velocity="0" />
  </joint>
  <link
    name="RR_calf">
    <inertial>
      <origin
        xyz="0.020656 0 -0.035012"
        rpy="0 0 0" />
      <mass
        value="0.95" />
      <inertia
        ixx="0.0014545"
        ixy="0"
        ixz="0.0003838"
        iyy="0.0017157"
        iyz="0"
        izz="0.00086925" />
    </inertial>
    <visual>
      <origin
        xyz="0 0 0"
        rpy="0 0 0" />
      <geometry>
        <mesh
          filename="/home/zenbot-ljl/placo_spider/spider_SLDASM_2m6d/meshes/RR_calf.STL" />
      </geometry>
      <material
        name="">
        <color
          rgba="0.79216 0.81961 0.93333 1" />
      </material>
    </visual>
    <collision>
      <origin
        xyz="0 0 0"
        rpy="0 0 0" />
      <geometry>
        <mesh
          filename="/home/zenbot-ljl/placo_spider/spider_SLDASM_2m6d/meshes/RR_calf.STL" />
      </geometry>
    </collision>
  </link>
  <joint
    name="RR_calf_joint_rev"
    type="revolute">
    <origin
      xyz="0.16 0 0"
      rpy="0 0 0" />
    <parent
      link="RR_thigh" />
    <child
      link="RR_calf" />
    <axis
      xyz="0 1 0" />
    <limit
      lower="-1.5707963268"
      upper="1.0471975512"
      effort="0"
      velocity="0" />
  </joint>
  <link
    name="RR_steer">
    <inertial>
      <origin
        xyz="-0.010789 0 -0.038549"
        rpy="0 0 0" />
      <mass
        value="0.4937" />
      <inertia
        ixx="0.00032831"
        ixy="0"
        ixz="-8.8866E-06"
        iyy="0.00032683"
        iyz="0"
        izz="0.00023698" />
    </inertial>
    <visual>
      <origin
        xyz="0 0 0"
        rpy="0 0 0" />
      <geometry>
        <mesh
          filename="/home/zenbot-ljl/placo_spider/spider_SLDASM_2m6d/meshes/RR_steer.STL" />
      </geometry>
      <material
        name="">
        <color
          rgba="1 1 1 1" />
      </material>
    </visual>
    <collision>
      <origin
        xyz="0 0 0"
        rpy="0 0 0" />
      <geometry>
        <mesh
          filename="/home/zenbot-ljl/placo_spider/spider_SLDASM_2m6d/meshes/RR_steer.STL" />
      </geometry>
    </collision>
  </link>
  <joint
    name="RR_steer_joint_rev"
    type="fixed">
    <origin
      xyz="0.033 0 -0.097"
      rpy="0 0 0" />
    <parent
      link="RR_calf" />
    <child
      link="RR_steer" />
    <!-- <axis
      xyz="0 0 1" />
    <limit
      lower="-0.34907"
      upper="1.5708"
      effort="0"
      velocity="0" /> -->
  </joint>
  <link
    name="RR_trans">
    <inertial>
      <origin
        xyz="-4.1E-05 -8.8E-05 -0.045108"
        rpy="0 0 0" />
      <mass
        value="0.4204" />
      <inertia
        ixx="0.00030185"
        ixy="-4.204E-07"
        ixz="8.408E-07"
        iyy="0.00030059"
        iyz="1.6816E-06"
        izz="0.00020305" />
    </inertial>
    <visual>
      <origin
        xyz="0 0 0"
        rpy="0 0 0" />
      <geometry>
        <mesh
          filename="/home/zenbot-ljl/placo_spider/spider_SLDASM_2m6d/meshes/RR_trans.STL" />
      </geometry>
      <material
        name="">
        <color
          rgba="0.79216 0.81961 0.93333 1" />
      </material>
    </visual>
    <collision>
      <origin
        xyz="0 0 0"
        rpy="0 0 0" />
      <geometry>
        <mesh
          filename="/home/zenbot-ljl/placo_spider/spider_SLDASM_2m6d/meshes/RR_trans.STL" />
      </geometry>
    </collision>
  </link>
  <joint
    name="RR_trans_joint_rev"
    type="fixed">
    <origin
      xyz="-0.00099998 0 -0.09"
      rpy="0 0 0" />
    <parent
      link="RR_steer" />
    <child
      link="RR_trans" />
    <!-- <axis
      xyz="0 1 0" />
    <limit
      lower="-1.5708"
      upper="0"
      effort="0"
      velocity="0" /> -->
  </joint>
  <link
    name="RR_wheel">
    <inertial>
      <origin
        xyz="0 0 0.022661"
        rpy="0 0 0" />
      <mass
        value="0.536" />
      <inertia
        ixx="0.00073807"
        ixy="0"
        ixz="0"
        iyy="0.00073807"
        iyz="0"
        izz="0.0011063" />
    </inertial>
    <visual>
      <origin
        xyz="0 0 0"
        rpy="0 0 0" />
      <geometry>
        <mesh
          filename="/home/zenbot-ljl/placo_spider/spider_SLDASM_2m6d/meshes/RR_wheel.STL" />
      </geometry>
      <material
        name="">
        <color
          rgba="1 1 1 1" />
      </material>
    </visual>
    <collision>
      <origin
        xyz="0 0 0"
        rpy="0 0 0" />
      <geometry>
        <mesh
          filename="/home/zenbot-ljl/placo_spider/spider_SLDASM_2m6d/meshes/RR_wheel.STL" />
      </geometry>
    </collision>
  </link>
  <joint
    name="RR_wheel_joint_con"
    type="fixed">
    <origin
      xyz="0 0 -0.083"
      rpy="0 0 0" />
    <parent
      link="RR_trans" />
    <child
      link="RR_wheel" />
    <!-- <axis
      xyz="0 0 1" />
    <limit
      lower="-1"
      upper="1"
      effort="0"
      velocity="0" /> -->
  </joint>
</robot>
  